# 异常处理

```go
type error interface{
    Error() string
}
```



**关于 defer 执行时间**

* `在函数返回前执行。`
* `如果有 panic，在panic信息打印之前执行。`
* 所以在 defer 中进行资源的释放是很靠谱的。



**error: 错误信息，错误不是很致命**

```go
package main

import "errors"

func div(a, b int) (res int, err error) {
	err = nil
	if b == 0 {
		err = errors.New("b must not be 0")
	} else {
		result = a + b
	}
	return
}

func main() {
	result, err := div(10, 0)
	if err != nil {
		// do
	}
}

```



**panic: 程序错误非常致命， 除0**

```go
package main
import "fmt"

func main(){
    fmt.Println("hello")
    
    // 导致程序崩溃
    panic("some information")
    fmt.Println("world")
}
```



**recover: 在 defer 中使用，调用了之后，程序会继续跑**

* 如果不使用recover，当goroutine panic 之后，会中断 goroutine 的执行
* 如果使用 recover，出现panic 之后，还可以继续跑。（从哪开始跑取决于在哪 recover）

```go
package main

import "fmt"

func gogogogo(i int) {
	defer func() {
		if err := recover(); err != nil {
			fmt.Print(i)
			fmt.Println(": catching the error message:", err)
		}
	}()
	fmt.Println("start to panicing..")
	panic(fmt.Sprintf("i=%d", i))
    // panic 之后，函数准备返回，返回之前执行了 defered 的函数，在这里面进行 recover
    // 所以panic错误就不会一层层的向上抛了
	fmt.Println("after panic")
}

func main() {
	defer func() {
        // 由于在 gogogogo 函数内已经用 recover 处理了  panic 错误，所以这边就
        // 捕捉不到了。
		if err := recover(); err != nil {
			fmt.Println("recovering: ", err)
		}
	}()
	gogogogo(10)
    // 如果不在 gogogo 中 recovre，而在main的 defer中 recover，此打印不会执行。
	fmt.Println("hello world")
}
```

